{"name": "CVE-2014-7185", "affected_release": [{"advisory": "RHSA-2015:1330", "release_date": "2015-07-20T00:00:00", "cpe": "cpe:/o:redhat:enterprise_linux:6", "product_name": "Red Hat Enterprise Linux 6", "package": "python-2.6.6-64.el6"}, {"advisory": "RHSA-2015:2101", "release_date": "2015-11-19T00:00:00", "cpe": "cpe:/o:redhat:enterprise_linux:7", "product_name": "Red Hat Enterprise Linux 7", "package": "python-2.7.5-34.el7"}, {"advisory": "RHSA-2015:1064", "release_date": "2015-06-04T00:00:00", "cpe": "cpe:/a:redhat:rhel_software_collections:2::el6", "product_name": "Red Hat Software Collections for Red Hat Enterprise Linux 6", "package": "python27-python-2.7.8-3.el6"}, {"advisory": "RHSA-2015:1064", "release_date": "2015-06-04T00:00:00", "cpe": "cpe:/a:redhat:rhel_software_collections:2::el7", "product_name": "Red Hat Software Collections for Red Hat Enterprise Linux 7", "package": "python27-python-2.7.8-3.el7"}], "public_date": "2014-06-23T00:00:00", "package_state": [{"fix_state": "Affected", "product_name": "Red Hat Software Collections 1 for Red Hat Enterprise Linux", "package_name": "python27-python", "cpe": "cpe:/a:redhat:rhel_software_collections:1"}, {"fix_state": "Not affected", "product_name": "Red Hat Software Collections 1 for Red Hat Enterprise Linux", "package_name": "python33-python", "cpe": "cpe:/a:redhat:rhel_software_collections:1"}, {"fix_state": "Not affected", "product_name": "Red Hat Software Collections for Red Hat Enterprise Linux", "package_name": "rh-python34-python", "cpe": "cpe:/a:redhat:rhel_software_collections:2"}, {"fix_state": "Will not fix", "product_name": "Red Hat Enterprise Linux 4", "package_name": "python", "cpe": "cpe:/o:redhat:enterprise_linux:4"}, {"fix_state": "Will not fix", "product_name": "Red Hat Enterprise Linux 5", "package_name": "python", "cpe": "cpe:/o:redhat:enterprise_linux:5"}], "document_distribution": "Copyright \u00a9 2016 Red Hat, Inc. All rights reserved.", "upstream_fix": "python 2.7.8", "threat_severity": "Low", "bugzilla": {"url": "https://bugzilla.redhat.com/show_bug.cgi?id=1146026", "description": "\nCVE-2014-7185 python: buffer() integer overflow leading to out of bounds read\n    ", "id": "1146026"}, "details": ["\nInteger overflow in bufferobject.c in Python before 2.7.8 allows context-dependent attackers to obtain sensitive information from process memory via a large size and offset in a \"buffer\" function.\n    ", "\nAn integer overflow flaw was found in the way the buffer() function handled its offset and size arguments. An attacker able to control those arguments could use this flaw to disclose portions of the application memory or cause it to crash.\n    "], "statement": "\nThis issue affects the versions of python as shipped with Red Hat Enterprise Linux 7. A future update may address this issue.\n\nRed Hat Enterprise Linux 5 is now in Production 3 Phase of the support and maintenance life cycle. This has been rated as having Low security impact and is not currently planned to be addressed in future updates. For additional information, refer to the Red Hat Enterprise Linux Life Cycle: https://access.redhat.com/support/policy/updates/errata/.\n    ", "cwe": "CWE-190->CWE-125->CWE-200", "cvss": {"cvss_scoring_vector": "AV:N/AC:H/Au:N/C:P/I:N/A:P", "status": "verified", "cvss_base_score": "4.0"}}