{"name": "CVE-2014-2667", "public_date": "2014-03-28T00:00:00", "package_state": [{"fix_state": "Not affected", "product_name": "Red Hat Software Collections 1 for Red Hat Enterprise Linux", "package_name": "python27-python", "cpe": "cpe:/a:redhat:rhel_software_collections:1"}, {"fix_state": "Will not fix", "product_name": "Red Hat Software Collections for Red Hat Enterprise Linux", "package_name": "python33-python", "cpe": "cpe:/a:redhat:rhel_software_collections:2"}, {"fix_state": "Not affected", "product_name": "Red Hat Enterprise Linux 5", "package_name": "python", "cpe": "cpe:/o:redhat:enterprise_linux:5"}, {"fix_state": "Not affected", "product_name": "Red Hat Enterprise Linux 6", "package_name": "python", "cpe": "cpe:/o:redhat:enterprise_linux:6"}, {"fix_state": "Not affected", "product_name": "Red Hat Enterprise Linux 7", "package_name": "python", "cpe": "cpe:/o:redhat:enterprise_linux:7"}], "document_distribution": "Copyright \u00a9 2016 Red Hat, Inc. All rights reserved.", "threat_severity": "Moderate", "bugzilla": {"url": "https://bugzilla.redhat.com/show_bug.cgi?id=1082177", "description": "\nCVE-2014-2667 python: os.makedirs(exist_ok=True) is not thread-safe in Python 3.x\n    ", "id": "1082177"}, "details": ["\nRace condition in the _get_masked_mode function in Lib/os.py in Python 3.2 through 3.5, when exist_ok is set to true and multiple threads are used, might allow local users to bypass intended file permissions by leveraging a separate application vulnerability before the umask has been set to the expected value.\n    "], "statement": "\nNot vulnerable. This issue did not affect the versions of python as shipped with Red Hat Enterprise Linux 5 and 6.\n    ", "cvss": {"cvss_scoring_vector": "AV:L/AC:L/Au:N/C:P/I:P/A:P", "status": "draft", "cvss_base_score": "4.6"}}