{"name": "CVE-2013-7040", "public_date": "2013-12-09T00:00:00", "package_state": [{"fix_state": "Will not fix", "product_name": "Red Hat Software Collections 1 for Red Hat Enterprise Linux", "package_name": "python27-python", "cpe": "cpe:/a:redhat:rhel_software_collections:1"}, {"fix_state": "Will not fix", "product_name": "Red Hat Software Collections 1 for Red Hat Enterprise Linux", "package_name": "python33-python", "cpe": "cpe:/a:redhat:rhel_software_collections:1"}, {"fix_state": "Will not fix", "product_name": "Red Hat Enterprise Linux 5", "package_name": "python", "cpe": "cpe:/o:redhat:enterprise_linux:5"}, {"fix_state": "Will not fix", "product_name": "Red Hat Enterprise Linux 6", "package_name": "python", "cpe": "cpe:/o:redhat:enterprise_linux:6"}, {"fix_state": "Will not fix", "product_name": "Red Hat Enterprise Linux 7", "package_name": "python", "cpe": "cpe:/o:redhat:enterprise_linux:7"}], "document_distribution": "Copyright \u00a9 2016 Red Hat, Inc. All rights reserved.", "threat_severity": "Moderate", "bugzilla": {"url": "https://bugzilla.redhat.com/show_bug.cgi?id=1039915", "description": "\nCVE-2013-7040 python: hash secret can be recovered remotely\n    ", "id": "1039915"}, "details": ["\nPython 2.7 before 3.4 only uses the last eight bits of the prefix to randomize hash values, which causes it to compute hash values without restricting the ability to trigger hash collisions predictably and makes it easier for context-dependent attackers to cause a denial of service (CPU consumption) via crafted input to an application that maintains a hash table.  NOTE: this vulnerability exists because of an incomplete fix for CVE-2012-1150.\n    "], "statement": "\nThis issue affects the version of python as shipped with Red Hat Enterprise Linux 5 and 6. There are currently no plans to fix this issue. For more details please refer to  https://bugzilla.redhat.com/show_bug.cgi?id=1039915#c4\n    ", "cvss": {"cvss_scoring_vector": "AV:N/AC:L/Au:N/C:N/I:N/A:P", "status": "draft", "cvss_base_score": "5.0"}}